2016-08-22 18:38:57,879 - teradata.udaexec - INFO - Initializing UdaExec...
2016-08-22 18:38:57,879 - teradata.udaexec - INFO - Reading config files: ['C:\\etc\\udaexec.ini: Not Found', 'C:\\Users\\BS255029\\udaexec.ini: Not Found', 'C:\\Users\\BS255029\\Documents\\Shift\\Shift\\mysite\\udaexec.ini: Found']
2016-08-22 18:38:57,879 - teradata.udaexec - INFO - Found run number file: "C:\Users\BS255029\Documents\Shift\Shift\mysite\.runNumber"
2016-08-22 18:38:57,880 - teradata.udaexec - INFO - Cleaning up log files older than 90 days.
2016-08-22 18:38:57,880 - teradata.udaexec - INFO - Removed 0 log files.
2016-08-22 18:38:57,890 - teradata.udaexec - INFO - Checkpoint file not found: C:\Users\BS255029\Documents\Shift\Shift\mysite\shiftroster.checkpoint
2016-08-22 18:38:57,891 - teradata.udaexec - INFO - No previous checkpoint found, executing from beginning...
2016-08-22 18:38:57,891 - teradata.udaexec - INFO - Execution Details:
/********************************************************************************
 * Application Name: shiftroster
 *          Version: 2
 *       Run Number: 20160822183857-59
 *             Host: WINBS255029-O9Y
 *         Platform: Windows-7-6.1.7601-SP1
 *          OS User: bs255029
 *   Python Version: 3.4.4
 *  Python Compiler: MSC v.1600 64 bit (AMD64)
 *     Python Build: ('v3.4.4:737efcadf5a6', 'Dec 20 2015 20:20:57')
 *  UdaExec Version: 15.10.0.17
 *     Program Name: manage.py
 *      Working Dir: C:\Users\BS255029\Documents\Shift\Shift\mysite
 *          Log Dir: C:\Users\BS255029\Documents\Shift\Shift\mysite\logs
 *         Log File: C:\Users\BS255029\Documents\Shift\Shift\mysite\logs\shiftroster.20160822183857-59.log
 *     Config Files: ['C:\\etc\\udaexec.ini: Not Found', 'C:\\Users\\BS255029\\udaexec.ini: Not Found', 'C:\\Users\\BS255029\\Documents\\Shift\\Shift\\mysite\\udaexec.ini: Found']
 *      Query Bands: ApplicationName=shiftroster;Version=2;JobID=20160822183857-59;ClientUser=bs255029;Production=False;udaAppLogFile=C:\Users\BS255029\Documents\Shift\Shift\mysite\logs\shiftroster.20160822183857-59.log;UtilityName=PyTd;UtilityVersion=15.10.0.17
********************************************************************************/
2016-08-22 18:38:57,892 - teradata.udaexec - INFO - Creating connection: {'method': 'odbc', 'password': 'XXXXXX', 'username': 'select_user', 'system': 'tiescfm01', 'externalDSN': 'TIES', 'charset': 'UTF8'}
2016-08-22 18:38:59,873 - teradata.udaexec - INFO - Connection successful. Duration: 1.981 seconds. Details: {'method': 'odbc', 'password': 'XXXXXX', 'username': 'select_user', 'system': 'tiescfm01', 'externalDSN': 'TIES', 'charset': 'UTF8'}
2016-08-22 18:38:59,896 - teradata.udaexec - INFO - Query Successful. Duration: 0.023 seconds, Rows: 2, Query: select * from trm.employee_detail where e_empid=10316 or e_empid=10317
2016-08-22 18:38:59,896 - django.request - ERROR - Internal Server Error: /shiftroster/test
Traceback (most recent call last):
  File "C:\Python34\lib\site-packages\django\core\handlers\exception.py", line 39, in inner
    response = get_response(request)
  File "C:\Python34\lib\site-packages\django\core\handlers\base.py", line 249, in _legacy_get_response
    response = self._get_response(request)
  File "C:\Python34\lib\site-packages\django\core\handlers\base.py", line 187, in _get_response
    response = self.process_exception_by_middleware(e, request)
  File "C:\Python34\lib\site-packages\django\core\handlers\base.py", line 185, in _get_response
    response = wrapped_callback(request, *callback_args, **callback_kwargs)
  File "C:\Users\BS255029\Documents\Shift\Shift\mysite\shiftroster\views.py", line 384, in test
    return HttpResponse(template_name.render(context,request,{'STATIC_URL': settings.STATIC_URL}))
TypeError: render() takes from 1 to 3 positional arguments but 4 were given
2016-08-22 18:40:07,567 - teradata.tdodbc - WARNING - 1 open connections found on exit, attempting to close...
2016-08-22 18:40:07,616 - teradata.udaexec - INFO - UdaExec exiting.
