2016-08-22 18:20:51,214 - teradata.udaexec - INFO - Initializing UdaExec...
2016-08-22 18:20:51,215 - teradata.udaexec - INFO - Reading config files: ['C:\\etc\\udaexec.ini: Not Found', 'C:\\Users\\BS255029\\udaexec.ini: Not Found', 'C:\\Users\\BS255029\\Documents\\Shift\\Shift\\mysite\\udaexec.ini: Found']
2016-08-22 18:20:51,215 - teradata.udaexec - INFO - Found run number file: "C:\Users\BS255029\Documents\Shift\Shift\mysite\.runNumber"
2016-08-22 18:20:51,215 - teradata.udaexec - INFO - Cleaning up log files older than 90 days.
2016-08-22 18:20:51,215 - teradata.udaexec - INFO - Removed 0 log files.
2016-08-22 18:20:51,223 - teradata.udaexec - INFO - Checkpoint file not found: C:\Users\BS255029\Documents\Shift\Shift\mysite\shiftroster.checkpoint
2016-08-22 18:20:51,224 - teradata.udaexec - INFO - No previous checkpoint found, executing from beginning...
2016-08-22 18:20:51,224 - teradata.udaexec - INFO - Execution Details:
/********************************************************************************
 * Application Name: shiftroster
 *          Version: 2
 *       Run Number: 20160822182051-58
 *             Host: WINBS255029-O9Y
 *         Platform: Windows-7-6.1.7601-SP1
 *          OS User: bs255029
 *   Python Version: 3.4.4
 *  Python Compiler: MSC v.1600 64 bit (AMD64)
 *     Python Build: ('v3.4.4:737efcadf5a6', 'Dec 20 2015 20:20:57')
 *  UdaExec Version: 15.10.0.17
 *     Program Name: manage.py
 *      Working Dir: C:\Users\BS255029\Documents\Shift\Shift\mysite
 *          Log Dir: C:\Users\BS255029\Documents\Shift\Shift\mysite\logs
 *         Log File: C:\Users\BS255029\Documents\Shift\Shift\mysite\logs\shiftroster.20160822182051-58.log
 *     Config Files: ['C:\\etc\\udaexec.ini: Not Found', 'C:\\Users\\BS255029\\udaexec.ini: Not Found', 'C:\\Users\\BS255029\\Documents\\Shift\\Shift\\mysite\\udaexec.ini: Found']
 *      Query Bands: ApplicationName=shiftroster;Version=2;JobID=20160822182051-58;ClientUser=bs255029;Production=False;udaAppLogFile=C:\Users\BS255029\Documents\Shift\Shift\mysite\logs\shiftroster.20160822182051-58.log;UtilityName=PyTd;UtilityVersion=15.10.0.17
********************************************************************************/
2016-08-22 18:20:51,225 - teradata.udaexec - INFO - Creating connection: {'username': 'select_user', 'charset': 'UTF8', 'password': 'XXXXXX', 'method': 'odbc', 'externalDSN': 'TIES', 'system': 'tiescfm01'}
2016-08-22 18:20:53,358 - django.request - ERROR - Internal Server Error: /shiftroster/home
Traceback (most recent call last):
  File "C:\Python34\lib\site-packages\django\core\handlers\exception.py", line 39, in inner
    response = get_response(request)
  File "C:\Python34\lib\site-packages\django\core\handlers\base.py", line 249, in _legacy_get_response
    response = self._get_response(request)
  File "C:\Python34\lib\site-packages\django\core\handlers\base.py", line 187, in _get_response
    response = self.process_exception_by_middleware(e, request)
  File "C:\Python34\lib\site-packages\django\core\handlers\base.py", line 185, in _get_response
    response = wrapped_callback(request, *callback_args, **callback_kwargs)
  File "C:\Users\BS255029\Documents\Shift\Shift\mysite\shiftroster\views.py", line 465, in home
    return render(req, 'main.html', {'STATIC_URL': settings.STATIC_URL})
NameError: name 'settings' is not defined
2016-08-22 18:20:54,102 - teradata.udaexec - INFO - Connection successful. Duration: 2.877 seconds. Details: {'username': 'select_user', 'charset': 'UTF8', 'password': 'XXXXXX', 'method': 'odbc', 'externalDSN': 'TIES', 'system': 'tiescfm01'}
2016-08-22 18:20:54,127 - teradata.udaexec - INFO - Query Successful. Duration: 0.025 seconds, Rows: 2, Query: select * from trm.employee_detail where e_empid=10316 or e_empid=10317
2016-08-22 18:21:33,981 - teradata.udaexec - INFO - UdaExec exiting.
